[INFO     2015-03-04 12:28:03,519 bulkloader.py] Logging to bulkloader-log-20150304.122803
[INFO     2015-03-04 12:28:03,519 bulkloader.py] Throttling transfers:
[INFO     2015-03-04 12:28:03,519 bulkloader.py] Bandwidth: 250000 bytes/second
[INFO     2015-03-04 12:28:03,520 bulkloader.py] HTTP connections: 8/second
[INFO     2015-03-04 12:28:03,520 bulkloader.py] Entities inserted/fetched/modified: 20/second
[INFO     2015-03-04 12:28:03,520 bulkloader.py] Batch Size: 10
[INFO     2015-03-04 12:28:03,551 bulkloader.py] Opening database: bulkloader-progress-20150304.122803.sql3
[DEBUG    2015-03-04 12:28:03,566 adaptive_thread_pool.py] [WorkerThread-0] WorkerThread: started
[DEBUG    2015-03-04 12:28:03,568 adaptive_thread_pool.py] [WorkerThread-1] WorkerThread: started
[DEBUG    2015-03-04 12:28:03,568 adaptive_thread_pool.py] [WorkerThread-2] WorkerThread: started
[DEBUG    2015-03-04 12:28:03,568 adaptive_thread_pool.py] [WorkerThread-3] WorkerThread: started
[DEBUG    2015-03-04 12:28:03,569 adaptive_thread_pool.py] [WorkerThread-4] WorkerThread: started
[DEBUG    2015-03-04 12:28:03,570 adaptive_thread_pool.py] [WorkerThread-5] WorkerThread: started
[DEBUG    2015-03-04 12:28:03,570 adaptive_thread_pool.py] [WorkerThread-6] WorkerThread: started
[DEBUG    2015-03-04 12:28:03,571 adaptive_thread_pool.py] [WorkerThread-7] WorkerThread: started
[DEBUG    2015-03-04 12:28:03,572 adaptive_thread_pool.py] [WorkerThread-8] WorkerThread: started
[DEBUG    2015-03-04 12:28:03,572 adaptive_thread_pool.py] [WorkerThread-9] WorkerThread: started
[DEBUG    2015-03-04 12:28:03,572 bulkloader.py] Configuring remote_api. url_path = /remote_api, servername = localhost:8080
[DEBUG    2015-03-04 12:28:05,997 bulkloader.py] Bulkloader using app_id: missy-go
[INFO     2015-03-04 12:28:05,997 bulkloader.py] Connecting to localhost:8080/remote_api
[ERROR    2015-03-04 12:29:21,193 bulkloader.py] Exception during authentication
Traceback (most recent call last):
  File "/Applications/GoogleAppEngineLauncher.app/Contents/Resources/GoogleAppEngine-default.bundle/Contents/Resources/google_appengine/google/appengine/tools/bulkloader.py", line 3466, in Run
    self.request_manager.Authenticate()
  File "/Applications/GoogleAppEngineLauncher.app/Contents/Resources/GoogleAppEngine-default.bundle/Contents/Resources/google_appengine/google/appengine/tools/bulkloader.py", line 1329, in Authenticate
    remote_api_stub.MaybeInvokeAuthentication()
  File "/Applications/GoogleAppEngineLauncher.app/Contents/Resources/GoogleAppEngine-default.bundle/Contents/Resources/google_appengine/google/appengine/ext/remote_api/remote_api_stub.py", line 889, in MaybeInvokeAuthentication
    datastore_stub._server.Send(datastore_stub._path, payload=None)
  File "/Applications/GoogleAppEngineLauncher.app/Contents/Resources/GoogleAppEngine-default.bundle/Contents/Resources/google_appengine/google/appengine/tools/appengine_rpc.py", line 426, in Send
    f = self.opener.open(req)
  File "/Library/Frameworks/Python.framework/Versions/2.7/lib/python2.7/urllib2.py", line 431, in open
    response = self._open(req, data)
  File "/Library/Frameworks/Python.framework/Versions/2.7/lib/python2.7/urllib2.py", line 449, in _open
    '_open', req)
  File "/Library/Frameworks/Python.framework/Versions/2.7/lib/python2.7/urllib2.py", line 409, in _call_chain
    result = func(*args)
  File "/Library/Frameworks/Python.framework/Versions/2.7/lib/python2.7/urllib2.py", line 1227, in http_open
    return self.do_open(httplib.HTTPConnection, req)
  File "/Library/Frameworks/Python.framework/Versions/2.7/lib/python2.7/urllib2.py", line 1197, in do_open
    raise URLError(err)
URLError: <urlopen error [Errno 60] Operation timed out>
[ERROR    2015-03-04 12:29:21,211 bulkloader.py] Authentication Failed: Incorrect credentials or unsupported authentication type (e.g. OpenId).
