[INFO     2015-03-04 12:10:54,247 bulkloader.py] Logging to bulkloader-log-20150304.121054
[INFO     2015-03-04 12:10:54,247 bulkloader.py] Throttling transfers:
[INFO     2015-03-04 12:10:54,248 bulkloader.py] Bandwidth: 250000 bytes/second
[INFO     2015-03-04 12:10:54,248 bulkloader.py] HTTP connections: 8/second
[INFO     2015-03-04 12:10:54,248 bulkloader.py] Entities inserted/fetched/modified: 20/second
[INFO     2015-03-04 12:10:54,248 bulkloader.py] Batch Size: 10
[INFO     2015-03-04 12:10:54,266 bulkloader.py] Opening database: bulkloader-progress-20150304.121054.sql3
[DEBUG    2015-03-04 12:10:54,289 adaptive_thread_pool.py] [WorkerThread-0] WorkerThread: started
[DEBUG    2015-03-04 12:10:54,291 adaptive_thread_pool.py] [WorkerThread-1] WorkerThread: started
[DEBUG    2015-03-04 12:10:54,292 adaptive_thread_pool.py] [WorkerThread-2] WorkerThread: started
[DEBUG    2015-03-04 12:10:54,293 adaptive_thread_pool.py] [WorkerThread-3] WorkerThread: started
[DEBUG    2015-03-04 12:10:54,294 adaptive_thread_pool.py] [WorkerThread-4] WorkerThread: started
[DEBUG    2015-03-04 12:10:54,294 adaptive_thread_pool.py] [WorkerThread-5] WorkerThread: started
[DEBUG    2015-03-04 12:10:54,294 adaptive_thread_pool.py] [WorkerThread-6] WorkerThread: started
[DEBUG    2015-03-04 12:10:54,295 adaptive_thread_pool.py] [WorkerThread-7] WorkerThread: started
[DEBUG    2015-03-04 12:10:54,295 adaptive_thread_pool.py] [WorkerThread-8] WorkerThread: started
[DEBUG    2015-03-04 12:10:54,295 adaptive_thread_pool.py] [WorkerThread-9] WorkerThread: started
[DEBUG    2015-03-04 12:10:54,295 bulkloader.py] Configuring remote_api. url_path = /_ah/remote_api, servername = 127.0.0.1:8088
[DEBUG    2015-03-04 12:10:54,318 bulkloader.py] Bulkloader using app_id: dev~missy-go
[INFO     2015-03-04 12:10:54,318 bulkloader.py] Connecting to 127.0.0.1:8088/_ah/remote_api
[ERROR    2015-03-04 12:10:54,334 bulkloader.py] Exception during authentication
Traceback (most recent call last):
  File "/Applications/GoogleAppEngineLauncher.app/Contents/Resources/GoogleAppEngine-default.bundle/Contents/Resources/google_appengine/google/appengine/tools/bulkloader.py", line 3466, in Run
    self.request_manager.Authenticate()
  File "/Applications/GoogleAppEngineLauncher.app/Contents/Resources/GoogleAppEngine-default.bundle/Contents/Resources/google_appengine/google/appengine/tools/bulkloader.py", line 1329, in Authenticate
    remote_api_stub.MaybeInvokeAuthentication()
  File "/Applications/GoogleAppEngineLauncher.app/Contents/Resources/GoogleAppEngine-default.bundle/Contents/Resources/google_appengine/google/appengine/ext/remote_api/remote_api_stub.py", line 889, in MaybeInvokeAuthentication
    datastore_stub._server.Send(datastore_stub._path, payload=None)
  File "/Applications/GoogleAppEngineLauncher.app/Contents/Resources/GoogleAppEngine-default.bundle/Contents/Resources/google_appengine/google/appengine/tools/appengine_rpc.py", line 426, in Send
    f = self.opener.open(req)
  File "/Library/Frameworks/Python.framework/Versions/2.7/lib/python2.7/urllib2.py", line 437, in open
    response = meth(req, response)
  File "/Library/Frameworks/Python.framework/Versions/2.7/lib/python2.7/urllib2.py", line 550, in http_response
    'http', request, response, code, msg, hdrs)
  File "/Library/Frameworks/Python.framework/Versions/2.7/lib/python2.7/urllib2.py", line 475, in error
    return self._call_chain(*args)
  File "/Library/Frameworks/Python.framework/Versions/2.7/lib/python2.7/urllib2.py", line 409, in _call_chain
    result = func(*args)
  File "/Library/Frameworks/Python.framework/Versions/2.7/lib/python2.7/urllib2.py", line 558, in http_error_default
    raise HTTPError(req.get_full_url(), code, msg, hdrs, fp)
HTTPError: HTTP Error 404: Not Found
[ERROR    2015-03-04 12:10:54,341 bulkloader.py] Authentication Failed: Incorrect credentials or unsupported authentication type (e.g. OpenId).
